<?xml version="1.0" ?>
<!-- =================================================================================== -->
<!-- |    This document was autogenerated by xacro from config/go.urdf.xacro           | -->
<!-- |    EDITING THIS FILE BY HAND IS NOT RECOMMENDED                                 | -->
<!-- =================================================================================== -->
<robot name="iiwa14">
  
    b'
  '
    b'
  '
    b'
  '
    b'
  '
    b'
  '
    b'
  '

  <!-- Rviz colors -->
  <!-- These define standard color names are that can be used elsewhere for
       improved visualization -->
  <link name="base_link"/>
  <!--use joints in the future to make this easier-->
  <link name="container_ramp">
    <collision>
      <origin rpy="-2.967 0 -2.336" xyz="-0.1352 0.6679 -0.0436"/>
      <geometry>
        <box size="0.175 0.4 0.2"/>
      </geometry>
    </collision>
    <visual>
      <origin rpy="-2.967 0 -2.336" xyz="-0.1352 0.6679 -0.0436"/>
      <geometry>
        <box size="0.175 0.4 0.2"/>
      </geometry>
    </visual>
    <collision>
      <origin rpy="0 1.5707963267948966 -2.336" xyz="-0.0011 0.537 0.0387"/>
      <geometry>
        <cylinder length="0.06" radius="0.025"/>
      </geometry>
    </collision>
    <visual>
      <origin rpy="0 1.5707963267948966 -2.336" xyz="-0.0011 0.537 0.0387"/>
      <geometry>
        <cylinder length="0.06" radius="0.025"/>
      </geometry>
    </visual>
  </link>
  <!-- Connects Assembly to parent -->
  <link name="container_drop_off"/>
  <joint name="base_link_to_container_drop_off" type="fixed">
    <parent link="base_link"/>
    <child link="container_drop_off"/>
    <origin rpy="0 0 0" xyz="0 -0.04134 0"/>
  </joint>
  <joint name="container_drop_off_to_container_ramp" type="fixed">
    <parent link="container_drop_off"/>
    <child link="container_ramp"/>
    <origin rpy="0 0 0" xyz="0 0 0"/>
  </joint>
  <drake:collision_filter_group name="container_drop_off">
    <drake:member link="container_ramp"/>
    <drake:ignored_collision_filter_group name="container_drop_off"/>
    <drake:ignored_collision_filter_group name="base"/>
  </drake:collision_filter_group>
  <link name="labeler_box">
    <collision>
      <origin rpy="0 0 0.36285395" xyz="-0.05394 -0.75164 0.1738 "/>
      <geometry>
        <box size="0.17907 0.24568 0.5"/>
      </geometry>
    </collision>
    <visual>
      <origin rpy="0 0 0.36285395" xyz="-0.05394 -0.75164 0.1738 "/>
      <geometry>
        <box size="0.17907 0.24568 0.5"/>
      </geometry>
    </visual>
    <collision>
      <origin rpy="0 0 0.362853645" xyz="-0.08998 -0.65669 0.02749 "/>
      <geometry>
        <box size="0.12243 0.1332 0.0408"/>
      </geometry>
    </collision>
    <visual>
      <origin rpy="0 0 0.362853645" xyz="-0.08998 -0.65669 0.02749 "/>
      <geometry>
        <box size="0.12243 0.1332 0.0408"/>
      </geometry>
    </visual>
  </link>
  <!-- Connects Assembly to parent -->
  <link name="labeler"/>
  <joint name="base_link_to_labeler" type="fixed">
    <parent link="base_link"/>
    <child link="labeler"/>
    <origin rpy="0 0 0" xyz="0 -0.04134 0"/>
  </joint>
  <joint name="labeler_to_labler" type="fixed">
    <parent link="labeler"/>
    <child link="labeler_box"/>
    <origin rpy="0 0 0" xyz="0 0 0"/>
  </joint>
  <drake:collision_filter_group name="labeler">
    <drake:member link="labeler_box"/>
    <drake:ignored_collision_filter_group name="labeler"/>
    <drake:ignored_collision_filter_group name="base"/>
  </drake:collision_filter_group>
  <link name="lidder_col">
    <collision>
      <origin rpy="0 0 0" xyz="0.28469 -0.8956145 0.07338 "/>
      <geometry>
        <cylinder length="0.3175" radius="0.1651"/>
      </geometry>
    </collision>
    <visual>
      <origin rpy="0 0 0" xyz="0.28469 -0.8956145 0.07338 "/>
      <geometry>
        <cylinder length="0.3175" radius="0.1651"/>
      </geometry>
    </visual>
    <collision>
      <origin rpy="0 0 0" xyz="0.15959 -0.7285345 0.07338 "/>
      <geometry>
        <cylinder length="0.3175" radius="0.04678"/>
      </geometry>
    </collision>
    <visual>
      <origin rpy="0 0 0" xyz="0.15959 -0.7285345 0.07338 "/>
      <geometry>
        <cylinder length="0.3175" radius="0.04678"/>
      </geometry>
    </visual>
  </link>
  <!-- Connects Assembly to parent -->
  <link name="lidder"/>
  <joint name="base_link_to_lidder" type="fixed">
    <parent link="base_link"/>
    <child link="lidder"/>
    <origin rpy="0 0 0" xyz="0 -0.04134 0"/>
  </joint>
  <joint name="lidder_to_lidder" type="fixed">
    <parent link="lidder"/>
    <child link="lidder_col"/>
    <origin rpy="0 0 0" xyz="0 0 0"/>
  </joint>
  <drake:collision_filter_group name="lidder">
    <drake:member link="lidder_col"/>
    <drake:ignored_collision_filter_group name="lidder"/>
    <drake:ignored_collision_filter_group name="labeler"/>
    <drake:ignored_collision_filter_group name="base"/>
  </drake:collision_filter_group>
  <!-- TODO: replace with auto-generated xacro/robot_state/urdf_gen_state_cg.xacro -->
  <link name="low_boy_3pan_with_hotel_pans"/>
  <link name="low_boy_3pan_east">
    <!-- side wall 1 -->
    <collision>
      <origin rpy="0 0 0" xyz="0 0.6369 -0.445"/>
      <geometry>
        <box size="1.2 0.3 0.9"/>
      </geometry>
    </collision>
    <visual>
      <origin rpy="0 0 0" xyz="0 0.6369 -0.445"/>
      <geometry>
        <box size="1.2 0.3 0.9"/>
      </geometry>
    </visual>
    <!-- side wall 2 -->
    <collision>
      <origin rpy="0 0 0" xyz="0 -0.6369 -0.445"/>
      <geometry>
        <box size="1.2 0.3 0.9"/>
      </geometry>
    </collision>
    <visual>
      <origin rpy="0 0 0" xyz="0 -0.6369 -0.445"/>
      <geometry>
        <box size="1.2 0.3 0.9"/>
      </geometry>
    </visual>
    <!-- wall close to robot -->
    <collision>
      <origin rpy="0 0 0" xyz="0.4151 0 -0.445"/>
      <geometry>
        <box size="0.3 1.2 0.9"/>
      </geometry>
    </collision>
    <visual>
      <origin rpy="0 0 0" xyz="0.4151 0 -0.445"/>
      <geometry>
        <box size="0.3 1.2 0.9"/>
      </geometry>
    </visual>
    <!-- wall far from robot -->
    <collision>
      <origin rpy="0 0 0" xyz="-0.4151 0 -0.445"/>
      <geometry>
        <box size="0.3 1.2 0.9"/>
      </geometry>
    </collision>
    <visual>
      <origin rpy="0 0 0" xyz="-0.4151 0 -0.445"/>
      <geometry>
        <box size="0.3 1.2 0.9"/>
      </geometry>
    </visual>
  </link>
  <joint name="low_boy_3pan_with_hotel_pans_to_low_boy_3pan_east" type="fixed">
    <parent link="low_boy_3pan_with_hotel_pans"/>
    <child link="low_boy_3pan_east"/>
    <origin rpy="0 0 0" xyz="0.4974 0 0"/>
  </joint>
  <link name="low_boy_3pan_west">
    <!-- side wall 1 -->
    <collision>
      <origin rpy="0 0 0" xyz="0 0.6369 -0.445"/>
      <geometry>
        <box size="1.2 0.3 0.9"/>
      </geometry>
    </collision>
    <visual>
      <origin rpy="0 0 0" xyz="0 0.6369 -0.445"/>
      <geometry>
        <box size="1.2 0.3 0.9"/>
      </geometry>
    </visual>
    <!-- side wall 2 -->
    <collision>
      <origin rpy="0 0 0" xyz="0 -0.6369 -0.445"/>
      <geometry>
        <box size="1.2 0.3 0.9"/>
      </geometry>
    </collision>
    <visual>
      <origin rpy="0 0 0" xyz="0 -0.6369 -0.445"/>
      <geometry>
        <box size="1.2 0.3 0.9"/>
      </geometry>
    </visual>
    <!-- wall close to robot -->
    <collision>
      <origin rpy="0 0 0" xyz="0.4151 0 -0.445"/>
      <geometry>
        <box size="0.3 1.2 0.9"/>
      </geometry>
    </collision>
    <visual>
      <origin rpy="0 0 0" xyz="0.4151 0 -0.445"/>
      <geometry>
        <box size="0.3 1.2 0.9"/>
      </geometry>
    </visual>
    <!-- wall far from robot -->
    <collision>
      <origin rpy="0 0 0" xyz="-0.4151 0 -0.445"/>
      <geometry>
        <box size="0.3 1.2 0.9"/>
      </geometry>
    </collision>
    <visual>
      <origin rpy="0 0 0" xyz="-0.4151 0 -0.445"/>
      <geometry>
        <box size="0.3 1.2 0.9"/>
      </geometry>
    </visual>
  </link>
  <joint name="low_boy_3pan_with_hotel_pans_to_low_boy_3pan_west" type="fixed">
    <parent link="low_boy_3pan_with_hotel_pans"/>
    <child link="low_boy_3pan_west"/>
    <origin rpy="0 0 3.141592653589793" xyz="-0.4974 0 0"/>
  </joint>
  <joint name="base_link_to_low_boy_3pan_with_hotel_pans" type="fixed">
    <parent link="base_link"/>
    <child link="low_boy_3pan_with_hotel_pans"/>
    <origin rpy="0 0 0" xyz="0 -0.04134 -0.0862"/>
  </joint>
  <!-- Following is groups of hotel pans connected to helper joints in the low boy. To change full-pan slot, change the xacro parent. Then modify xyz for appropriate placement.-->
  <!-- Left robot section -->
  <link name="front_pans_left"/>
  <link name="back_pans_left"/>
  <link name="front_pans_center"/>
  <joint name="low_boy_3pan_with_hotel_pans_to_front_pans_center" type="fixed">
    <parent link="low_boy_3pan_with_hotel_pans"/>
    <child link="front_pans_center"/>
    <origin rpy="0 0 0" xyz="0.508763 0.024999999999999994 0"/>
  </joint>
  <link name="third_vine_corner_010_020"/>
  <joint name="front_pans_center_to_third_vine_corner_010_020" type="fixed">
    <parent link="front_pans_center"/>
    <child link="third_vine_corner_010_020"/>
    <origin rpy="0 0 0" xyz="-0.08816666666666667 0.1625 0"/>
  </joint>
  <link name="third_vine_corner_000_010"/>
  <joint name="front_pans_center_to_third_vine_corner_000_010" type="fixed">
    <parent link="front_pans_center"/>
    <child link="third_vine_corner_000_010"/>
    <origin rpy="0 0 0" xyz="0.08816666666666667 0.1625 0"/>
  </joint>
  <link name="back_pans_center"/>
  <joint name="low_boy_3pan_with_hotel_pans_to_back_pans_center" type="fixed">
    <parent link="low_boy_3pan_with_hotel_pans"/>
    <child link="back_pans_center"/>
    <origin rpy="0 0 3.141592653589793" xyz="-0.496763 0.024999999999999994 0"/>
  </joint>
  <joint name="low_boy_3pan_with_hotel_pans_to_front_pans_left" type="fixed">
    <parent link="low_boy_3pan_with_hotel_pans"/>
    <child link="front_pans_left"/>
    <origin rpy="0 0 0" xyz="0.508763 0.1875 0"/>
  </joint>
  <joint name="low_boy_3pan_with_hotel_pans_to_back_pans_left" type="fixed">
    <parent link="low_boy_3pan_with_hotel_pans"/>
    <child link="back_pans_left"/>
    <origin rpy="0 0 3.141592653589793" xyz="-0.496763 0.1875 0"/>
  </joint>
  <link name="front_pans_right"/>
  <link name="back_pans_right"/>
  <joint name="low_boy_3pan_with_hotel_pans_to_front_pans_right" type="fixed">
    <parent link="low_boy_3pan_with_hotel_pans"/>
    <child link="front_pans_right"/>
    <origin rpy="0 0 0" xyz="0.508763 -0.1875 0"/>
  </joint>
  <joint name="low_boy_3pan_with_hotel_pans_to_back_pans_right" type="fixed">
    <parent link="low_boy_3pan_with_hotel_pans"/>
    <child link="back_pans_right"/>
    <origin rpy="0 0 3.141592653589793" xyz="-0.496763 -0.1875 0"/>
  </joint>
  <!-- Connects Assembly to parent -->
  <link name="sneeze_guard"/>
  <joint name="low_boy_3pan_with_hotel_pans_to_sneeze_guard" type="fixed">
    <parent link="low_boy_3pan_with_hotel_pans"/>
    <child link="sneeze_guard"/>
    <origin rpy="0 0 3.141592653589793" xyz="0 0 0"/>
  </joint>
  <link name="sneeze_guard_west_wall">
    <collision>
      <origin xyz="0.793725 -0.1 0.851917"/>
      <geometry>
        <box size="1.58745 0.2 1.703834"/>
      </geometry>
    </collision>
    <visual>
      <origin xyz="0.793725 -0.1 0.851917"/>
      <geometry>
        <box size="1.58745 0.2 1.703834"/>
      </geometry>
    </visual>
  </link>
  <link name="sneeze_guard_east_wall">
    <collision>
      <origin xyz="0.793725 0.1 0.851917"/>
      <geometry>
        <box size="1.58745 0.2 1.703834"/>
      </geometry>
    </collision>
    <visual>
      <origin xyz="0.793725 0.1 0.851917"/>
      <geometry>
        <box size="1.58745 0.2 1.703834"/>
      </geometry>
    </visual>
  </link>
  <link name="sneeze_guard_side_wall_northeast">
    <collision>
      <origin xyz="0.5334 -0.1 1.004317"/>
      <geometry>
        <box size="1.0668 0.2 1.399034"/>
      </geometry>
    </collision>
    <visual>
      <origin xyz="0.5334 -0.1 1.004317"/>
      <geometry>
        <box size="1.0668 0.2 1.399034"/>
      </geometry>
    </visual>
    <collision>
      <origin xyz="0.266954 -0.1 0.15239999999999998"/>
      <geometry>
        <box size="0.533908 0.2 0.30479999999999996"/>
      </geometry>
    </collision>
    <visual>
      <origin xyz="0.266954 -0.1 0.15239999999999998"/>
      <geometry>
        <box size="0.533908 0.2 0.30479999999999996"/>
      </geometry>
    </visual>
  </link>
  <link name="sneeze_guard_side_wall_northwest">
    <collision>
      <origin xyz="0.5334 0.1 1.004317"/>
      <geometry>
        <box size="1.0668 0.2 1.399034"/>
      </geometry>
    </collision>
    <visual>
      <origin xyz="0.5334 0.1 1.004317"/>
      <geometry>
        <box size="1.0668 0.2 1.399034"/>
      </geometry>
    </visual>
    <collision>
      <origin xyz="0.266954 0.1 0.15239999999999998"/>
      <geometry>
        <box size="0.533908 0.2 0.30479999999999996"/>
      </geometry>
    </collision>
    <visual>
      <origin xyz="0.266954 0.1 0.15239999999999998"/>
      <geometry>
        <box size="0.533908 0.2 0.30479999999999996"/>
      </geometry>
    </visual>
  </link>
  <link name="sneeze_guard_side_wall_southeast">
    <collision>
      <origin xyz="0.202739 0.1 0.851917"/>
      <geometry>
        <box size="0.405478 0.2 1.703834"/>
      </geometry>
    </collision>
    <visual>
      <origin xyz="0.202739 0.1 0.851917"/>
      <geometry>
        <box size="0.405478 0.2 1.703834"/>
      </geometry>
    </visual>
  </link>
  <link name="sneeze_guard_side_wall_southeast_lidding_sideflap">
    <collision>
      <origin xyz="0.26454099999999997 0.1 0.851917"/>
      <geometry>
        <box size="0.5290819999999999 0.2 1.703834"/>
      </geometry>
    </collision>
    <visual>
      <origin xyz="0.26454099999999997 0.1 0.851917"/>
      <geometry>
        <box size="0.5290819999999999 0.2 1.703834"/>
      </geometry>
    </visual>
  </link>
  <link name="sneeze_guard_side_wall_southeast_lidding_backflap">
    <collision>
      <origin xyz="0.3654299999999999 0.1 0.851917"/>
      <geometry>
        <box size="0.7308599999999998 0.2 1.703834"/>
      </geometry>
    </collision>
    <visual>
      <origin xyz="0.3654299999999999 0.1 0.851917"/>
      <geometry>
        <box size="0.7308599999999998 0.2 1.703834"/>
      </geometry>
    </visual>
  </link>
  <joint name="sneeze_guard_side_wall_southeast_to_lidding_sideflap" type="fixed">
    <parent link="sneeze_guard_side_wall_southeast"/>
    <child link="sneeze_guard_side_wall_southeast_lidding_sideflap"/>
    <origin rpy="0 0 1.5707963267948966" xyz="0.405478 0 0"/>
  </joint>
  <joint name="sneeze_guard_side_wall_southeast_lidding_sideflap_to_backflap" type="fixed">
    <parent link="sneeze_guard_side_wall_southeast_lidding_sideflap"/>
    <child link="sneeze_guard_side_wall_southeast_lidding_backflap"/>
    <origin rpy="0 0 -1.5707963267948966" xyz="0.5290819999999999 0.2 0"/>
  </joint>
  <link name="sneeze_guard_side_wall_southwest">
    <collision>
      <origin xyz="0.197739 -0.1 0.851917"/>
      <geometry>
        <box size="0.395478 0.2 1.703834"/>
      </geometry>
    </collision>
    <visual>
      <origin xyz="0.197739 -0.1 0.851917"/>
      <geometry>
        <box size="0.395478 0.2 1.703834"/>
      </geometry>
    </visual>
  </link>
  <link name="sneeze_guard_side_wall_southwest_singulator_sideflap">
    <collision>
      <origin xyz="0.221996 -0.1 0.851917"/>
      <geometry>
        <box size="0.443992 0.2 1.703834"/>
      </geometry>
    </collision>
    <visual>
      <origin xyz="0.221996 -0.1 0.851917"/>
      <geometry>
        <box size="0.443992 0.2 1.703834"/>
      </geometry>
    </visual>
  </link>
  <link name="sneeze_guard_side_wall_southwest_singulator_backflap">
    <collision>
      <origin xyz="0.5654299999999999 -0.1 0.851917"/>
      <geometry>
        <box size="1.1308599999999998 0.2 1.703834"/>
      </geometry>
    </collision>
    <visual>
      <origin xyz="0.5654299999999999 -0.1 0.851917"/>
      <geometry>
        <box size="1.1308599999999998 0.2 1.703834"/>
      </geometry>
    </visual>
  </link>
  <joint name="sneeze_guard_side_wall_southwest_to_singulator_sideflap" type="fixed">
    <parent link="sneeze_guard_side_wall_southwest"/>
    <child link="sneeze_guard_side_wall_southwest_singulator_sideflap"/>
    <origin rpy="0 0 -1.5707963267948966" xyz="0.395478 0 0"/>
  </joint>
  <joint name="sneeze_guard_side_wall_southwest_singulator_sideflap_to_backflap" type="fixed">
    <parent link="sneeze_guard_side_wall_southwest_singulator_sideflap"/>
    <child link="sneeze_guard_side_wall_southwest_singulator_backflap"/>
    <origin rpy="0 0 1.5707963267948966" xyz="0.443992 -0.2 0"/>
  </joint>
  <joint name="sneeze_guard_to_sneeze_guard_west_wall" type="fixed">
    <parent link="sneeze_guard"/>
    <child link="sneeze_guard_west_wall"/>
    <origin rpy="0 0 1.5707963267948966" xyz="0.9530080000000001 -0.75753 0"/>
  </joint>
  <joint name="sneeze_guard_to_sneeze_guard_east_wall" type="fixed">
    <parent link="sneeze_guard"/>
    <child link="sneeze_guard_east_wall"/>
    <origin rpy="0 0 1.5707963267948966" xyz="-0.9530080000000001 -0.8329679999999999 0"/>
  </joint>
  <joint name="sneeze_guard_to_sneeze_guard_side_wall_southeast" type="fixed">
    <parent link="sneeze_guard"/>
    <child link="sneeze_guard_side_wall_southeast"/>
    <!-- bump in 2.5cm to match real life as measured in RViz -->
    <origin rpy="0 0 0" xyz="-0.9530080000000001 0.53253 0"/>
  </joint>
  <joint name="sneeze_guard_to_sneeze_guard_side_wall_southwest" type="fixed">
    <parent link="sneeze_guard"/>
    <child link="sneeze_guard_side_wall_southwest"/>
    <origin rpy="0 0 3.141592653589793" xyz="0.9530080000000001 0.632968 0"/>
  </joint>
  <joint name="sneeze_guard_to_sneeze_guard_side_wall_northeast" type="fixed">
    <parent link="sneeze_guard"/>
    <child link="sneeze_guard_side_wall_northeast"/>
    <origin rpy="0 0 0" xyz="-0.9530080000000001 -0.632968 0"/>
  </joint>
  <joint name="sneeze_guard_to_sneeze_guard_side_wall_northwest" type="fixed">
    <parent link="sneeze_guard"/>
    <child link="sneeze_guard_side_wall_northwest"/>
    <origin rpy="0 0 3.141592653589793" xyz="0.9530080000000001 -0.55753 0"/>
  </joint>
  <drake:collision_filter_group name="sneeze_guard">
    <drake:member link="sneeze_guard_west_wall"/>
    <drake:member link="sneeze_guard_east_wall"/>
    <drake:member link="sneeze_guard_side_wall_southeast"/>
    <drake:member link="sneeze_guard_side_wall_northeast"/>
    <drake:member link="sneeze_guard_side_wall_southwest"/>
    <drake:member link="sneeze_guard_side_wall_northwest"/>
    <drake:ignored_collision_filter_group name="sneeze_guard"/>
    <drake:ignored_collision_filter_group name="base"/>
  </drake:collision_filter_group>
  <!-- <xacro:property name="use_full_pans" value="${target_container.find('hotel_pan_full_6in') > -1}"/> -->
  <link name="hotel_pan_third_6in_000">
    <!-- simpler, box collision geo when we don't care about serving from this pan -->
    <!-- TODO: bounding box for racked utensil -->
    <collision>
      <origin rpy="0 0 0" xyz="0 0 0.0834"/>
      <geometry>
        <box size="0.35 0.19 0.17"/>
      </geometry>
    </collision>
    <visual>
      <origin rpy="0 0 0" xyz="0 0 0.0834"/>
      <geometry>
        <box size="0.35 0.19 0.17"/>
      </geometry>
    </visual>
    <!-- accurate collision geo for pan -->
    <!-- TODO: fix collision geo, this is just copied over from hotel_pan_sixth_6in -->
  </link>
  <joint name="front_pans_center_to_hotel_pan_third_6in_000" type="fixed">
    <origin rpy="0 0 -1.5707963267948966" xyz="0.17633333333333334 0.325 -0.175"/>
    <parent link="front_pans_center"/>
    <child link="hotel_pan_third_6in_000"/>
  </joint>
  <link name="hotel_pan_third_6in_010">
    <!-- simpler, box collision geo when we don't care about serving from this pan -->
    <!-- TODO: bounding box for racked utensil -->
    <collision>
      <origin rpy="0 0 0" xyz="0 0 0.0834"/>
      <geometry>
        <box size="0.35 0.19 0.17"/>
      </geometry>
    </collision>
    <visual>
      <origin rpy="0 0 0" xyz="0 0 0.0834"/>
      <geometry>
        <box size="0.35 0.19 0.17"/>
      </geometry>
    </visual>
    <!-- accurate collision geo for pan -->
    <!-- TODO: fix collision geo, this is just copied over from hotel_pan_sixth_6in -->
  </link>
  <joint name="front_pans_center_to_hotel_pan_third_6in_010" type="fixed">
    <origin rpy="0 0 -1.5707963267948966" xyz="0 0.325 -0.175"/>
    <parent link="front_pans_center"/>
    <child link="hotel_pan_third_6in_010"/>
  </joint>
  <link name="hotel_pan_third_6in_020">
    <!-- simpler, box collision geo when we don't care about serving from this pan -->
    <!-- TODO: bounding box for racked utensil -->
    <collision>
      <origin rpy="0 0 0" xyz="0 0 0.0834"/>
      <geometry>
        <box size="0.35 0.19 0.17"/>
      </geometry>
    </collision>
    <visual>
      <origin rpy="0 0 0" xyz="0 0 0.0834"/>
      <geometry>
        <box size="0.35 0.19 0.17"/>
      </geometry>
    </visual>
    <!-- accurate collision geo for pan -->
    <!-- TODO: fix collision geo, this is just copied over from hotel_pan_sixth_6in -->
  </link>
  <joint name="front_pans_center_to_hotel_pan_third_6in_020" type="fixed">
    <origin rpy="0 0 -1.5707963267948966" xyz="-0.17633333333333334 0.325 -0.175"/>
    <parent link="front_pans_center"/>
    <child link="hotel_pan_third_6in_020"/>
  </joint>
  <link name="hotel_pan_full_6in_001">
    <!-- simpler, box collision geo when we don't care about serving from this pan -->
    <!-- TODO: bounding box for racked utensil -->
    <collision>
      <origin rpy="0 0 -1.5707963267948966" xyz="0 0 0.0834"/>
      <geometry>
        <box size="0.53 0.34 0.17"/>
      </geometry>
    </collision>
    <visual>
      <origin rpy="0 0 -1.5707963267948966" xyz="0 0 0.0834"/>
      <geometry>
        <box size="0.53 0.34 0.17"/>
      </geometry>
    </visual>
    <!-- accurate collision geo for pan -->
    <!-- TODO: fix collision geo, this is just copied over from hotel_pan_sixth_6in -->
    <!-- Should be accuate now, measured manually and cross referenced to online vendors -->
  </link>
  <joint name="front_pans_center_to_hotel_pan_full_6in_001" type="fixed">
    <origin rpy="0 0 -1.5707963267948966" xyz="0 0.0 -0.175"/>
    <parent link="front_pans_center"/>
    <child link="hotel_pan_full_6in_001"/>
  </joint>
  <link name="hotel_pan_sixth_6in_004">
    <!-- simpler, box collision geo when we don't care about serving from this pan -->
    <!-- TODO: bounding box for racked utensil -->
    <collision>
      <origin rpy="0 0 0" xyz="0 0 0.0834"/>
      <geometry>
        <box size="0.175 0.19 0.17"/>
      </geometry>
    </collision>
    <visual>
      <origin rpy="0 0 0" xyz="0 0 0.0834"/>
      <geometry>
        <box size="0.175 0.19 0.17"/>
      </geometry>
    </visual>
    <!-- accurate collision geo for pan -->
  </link>
  <joint name="front_pans_center_to_hotel_pan_sixth_6in_004" type="fixed">
    <origin rpy="0 0 -1.5707963267948966" xyz="0.17633333333333334  -0.24375000000000002 -0.175"/>
    <parent link="front_pans_center"/>
    <child link="hotel_pan_sixth_6in_004"/>
  </joint>
  <link name="hotel_pan_sixth_6in_014">
    <!-- simpler, box collision geo when we don't care about serving from this pan -->
    <!-- TODO: bounding box for racked utensil -->
    <collision>
      <origin rpy="0 0 0" xyz="0 0 0.0834"/>
      <geometry>
        <box size="0.175 0.19 0.17"/>
      </geometry>
    </collision>
    <visual>
      <origin rpy="0 0 0" xyz="0 0 0.0834"/>
      <geometry>
        <box size="0.175 0.19 0.17"/>
      </geometry>
    </visual>
    <!-- accurate collision geo for pan -->
  </link>
  <joint name="front_pans_center_to_hotel_pan_sixth_6in_014" type="fixed">
    <origin rpy="0 0 -1.5707963267948966" xyz="0  -0.24375000000000002 -0.175"/>
    <parent link="front_pans_center"/>
    <child link="hotel_pan_sixth_6in_014"/>
  </joint>
  <link name="hotel_pan_sixth_6in_024">
    <!-- simpler, box collision geo when we don't care about serving from this pan -->
    <!-- TODO: bounding box for racked utensil -->
    <collision>
      <origin rpy="0 0 0" xyz="0 0 0.0834"/>
      <geometry>
        <box size="0.175 0.19 0.17"/>
      </geometry>
    </collision>
    <visual>
      <origin rpy="0 0 0" xyz="0 0 0.0834"/>
      <geometry>
        <box size="0.175 0.19 0.17"/>
      </geometry>
    </visual>
    <!-- accurate collision geo for pan -->
  </link>
  <joint name="front_pans_center_to_hotel_pan_sixth_6in_024" type="fixed">
    <origin rpy="0 0 -1.5707963267948966" xyz="-0.17633333333333334  -0.24375000000000002 -0.175"/>
    <parent link="front_pans_center"/>
    <child link="hotel_pan_sixth_6in_024"/>
  </joint>
  <link name="hotel_pan_sixth_6in_005">
    <!-- simpler, box collision geo when we don't care about serving from this pan -->
    <!-- TODO: bounding box for racked utensil -->
    <collision>
      <origin rpy="0 0 0" xyz="0 0 0.0834"/>
      <geometry>
        <box size="0.175 0.19 0.17"/>
      </geometry>
    </collision>
    <visual>
      <origin rpy="0 0 0" xyz="0 0 0.0834"/>
      <geometry>
        <box size="0.175 0.19 0.17"/>
      </geometry>
    </visual>
    <!-- accurate collision geo for pan -->
  </link>
  <joint name="front_pans_center_to_hotel_pan_sixth_6in_005" type="fixed">
    <origin rpy="0 0 -1.5707963267948966" xyz="0.17633333333333334  -0.40625 -0.175"/>
    <parent link="front_pans_center"/>
    <child link="hotel_pan_sixth_6in_005"/>
  </joint>
  <link name="hotel_pan_sixth_6in_015">
    <!-- simpler, box collision geo when we don't care about serving from this pan -->
    <!-- TODO: bounding box for racked utensil -->
    <collision>
      <origin rpy="0 0 0" xyz="0 0 0.0834"/>
      <geometry>
        <box size="0.175 0.19 0.17"/>
      </geometry>
    </collision>
    <visual>
      <origin rpy="0 0 0" xyz="0 0 0.0834"/>
      <geometry>
        <box size="0.175 0.19 0.17"/>
      </geometry>
    </visual>
    <!-- accurate collision geo for pan -->
  </link>
  <joint name="front_pans_center_to_hotel_pan_sixth_6in_015" type="fixed">
    <origin rpy="0 0 -1.5707963267948966" xyz="0  -0.40625 -0.175"/>
    <parent link="front_pans_center"/>
    <child link="hotel_pan_sixth_6in_015"/>
  </joint>
  <link name="hotel_pan_sixth_6in_025">
    <!-- simpler, box collision geo when we don't care about serving from this pan -->
    <!-- TODO: bounding box for racked utensil -->
    <collision>
      <origin rpy="0 0 0" xyz="0 0 0.0834"/>
      <geometry>
        <box size="0.175 0.19 0.17"/>
      </geometry>
    </collision>
    <visual>
      <origin rpy="0 0 0" xyz="0 0 0.0834"/>
      <geometry>
        <box size="0.175 0.19 0.17"/>
      </geometry>
    </visual>
    <!-- accurate collision geo for pan -->
  </link>
  <joint name="front_pans_center_to_hotel_pan_sixth_6in_025" type="fixed">
    <origin rpy="0 0 -1.5707963267948966" xyz="-0.17633333333333334  -0.40625 -0.175"/>
    <parent link="front_pans_center"/>
    <child link="hotel_pan_sixth_6in_025"/>
  </joint>
  <link name="hotel_pan_full_6in_200">
    <!-- simpler, box collision geo when we don't care about serving from this pan -->
    <!-- TODO: bounding box for racked utensil -->
    <collision>
      <origin rpy="0 0 -1.5707963267948966" xyz="0 0 0.0834"/>
      <geometry>
        <box size="0.53 0.34 0.17"/>
      </geometry>
    </collision>
    <visual>
      <origin rpy="0 0 -1.5707963267948966" xyz="0 0 0.0834"/>
      <geometry>
        <box size="0.53 0.34 0.17"/>
      </geometry>
    </visual>
    <!-- accurate collision geo for pan -->
    <!-- TODO: fix collision geo, this is just copied over from hotel_pan_sixth_6in -->
    <!-- Should be accuate now, measured manually and cross referenced to online vendors -->
  </link>
  <joint name="back_pans_center_to_hotel_pan_full_6in_200" type="fixed">
    <origin rpy="0 0 -1.5707963267948966" xyz="0 0.325 -0.175"/>
    <parent link="back_pans_center"/>
    <child link="hotel_pan_full_6in_200"/>
  </joint>
  <link name="hotel_pan_sixth_6in_202">
    <!-- simpler, box collision geo when we don't care about serving from this pan -->
    <!-- TODO: bounding box for racked utensil -->
    <collision>
      <origin rpy="0 0 0" xyz="0 0 0.0834"/>
      <geometry>
        <box size="0.175 0.19 0.17"/>
      </geometry>
    </collision>
    <visual>
      <origin rpy="0 0 0" xyz="0 0 0.0834"/>
      <geometry>
        <box size="0.175 0.19 0.17"/>
      </geometry>
    </visual>
    <!-- accurate collision geo for pan -->
  </link>
  <joint name="back_pans_center_to_hotel_pan_sixth_6in_202" type="fixed">
    <origin rpy="0 0 -1.5707963267948966" xyz="0.17633333333333334  0.08125 -0.175"/>
    <parent link="back_pans_center"/>
    <child link="hotel_pan_sixth_6in_202"/>
  </joint>
  <link name="hotel_pan_sixth_6in_212">
    <!-- simpler, box collision geo when we don't care about serving from this pan -->
    <!-- TODO: bounding box for racked utensil -->
    <collision>
      <origin rpy="0 0 0" xyz="0 0 0.0834"/>
      <geometry>
        <box size="0.175 0.19 0.17"/>
      </geometry>
    </collision>
    <visual>
      <origin rpy="0 0 0" xyz="0 0 0.0834"/>
      <geometry>
        <box size="0.175 0.19 0.17"/>
      </geometry>
    </visual>
    <!-- accurate collision geo for pan -->
  </link>
  <joint name="back_pans_center_to_hotel_pan_sixth_6in_212" type="fixed">
    <origin rpy="0 0 -1.5707963267948966" xyz="0  0.08125 -0.175"/>
    <parent link="back_pans_center"/>
    <child link="hotel_pan_sixth_6in_212"/>
  </joint>
  <link name="hotel_pan_sixth_6in_222">
    <!-- simpler, box collision geo when we don't care about serving from this pan -->
    <!-- TODO: bounding box for racked utensil -->
    <collision>
      <origin rpy="0 0 0" xyz="0 0 0.0834"/>
      <geometry>
        <box size="0.175 0.19 0.17"/>
      </geometry>
    </collision>
    <visual>
      <origin rpy="0 0 0" xyz="0 0 0.0834"/>
      <geometry>
        <box size="0.175 0.19 0.17"/>
      </geometry>
    </visual>
    <!-- accurate collision geo for pan -->
  </link>
  <joint name="back_pans_center_to_hotel_pan_sixth_6in_222" type="fixed">
    <origin rpy="0 0 -1.5707963267948966" xyz="-0.17633333333333334  0.08125 -0.175"/>
    <parent link="back_pans_center"/>
    <child link="hotel_pan_sixth_6in_222"/>
  </joint>
  <link name="hotel_pan_sixth_6in_203">
    <!-- simpler, box collision geo when we don't care about serving from this pan -->
    <!-- TODO: bounding box for racked utensil -->
    <collision>
      <origin rpy="0 0 0" xyz="0 0 0.0834"/>
      <geometry>
        <box size="0.175 0.19 0.17"/>
      </geometry>
    </collision>
    <visual>
      <origin rpy="0 0 0" xyz="0 0 0.0834"/>
      <geometry>
        <box size="0.175 0.19 0.17"/>
      </geometry>
    </visual>
    <!-- accurate collision geo for pan -->
  </link>
  <joint name="back_pans_center_to_hotel_pan_sixth_6in_203" type="fixed">
    <origin rpy="0 0 -1.5707963267948966" xyz="0.17633333333333334  -0.08125 -0.175"/>
    <parent link="back_pans_center"/>
    <child link="hotel_pan_sixth_6in_203"/>
  </joint>
  <link name="hotel_pan_sixth_6in_213">
    <!-- simpler, box collision geo when we don't care about serving from this pan -->
    <!-- TODO: bounding box for racked utensil -->
    <collision>
      <origin rpy="0 0 0" xyz="0 0 0.0834"/>
      <geometry>
        <box size="0.175 0.19 0.17"/>
      </geometry>
    </collision>
    <visual>
      <origin rpy="0 0 0" xyz="0 0 0.0834"/>
      <geometry>
        <box size="0.175 0.19 0.17"/>
      </geometry>
    </visual>
    <!-- accurate collision geo for pan -->
  </link>
  <joint name="back_pans_center_to_hotel_pan_sixth_6in_213" type="fixed">
    <origin rpy="0 0 -1.5707963267948966" xyz="0  -0.08125 -0.175"/>
    <parent link="back_pans_center"/>
    <child link="hotel_pan_sixth_6in_213"/>
  </joint>
  <link name="hotel_pan_sixth_6in_223">
    <!-- simpler, box collision geo when we don't care about serving from this pan -->
    <!-- TODO: bounding box for racked utensil -->
    <collision>
      <origin rpy="0 0 0" xyz="0 0 0.0834"/>
      <geometry>
        <box size="0.175 0.19 0.17"/>
      </geometry>
    </collision>
    <visual>
      <origin rpy="0 0 0" xyz="0 0 0.0834"/>
      <geometry>
        <box size="0.175 0.19 0.17"/>
      </geometry>
    </visual>
    <!-- accurate collision geo for pan -->
  </link>
  <joint name="back_pans_center_to_hotel_pan_sixth_6in_223" type="fixed">
    <origin rpy="0 0 -1.5707963267948966" xyz="-0.17633333333333334  -0.08125 -0.175"/>
    <parent link="back_pans_center"/>
    <child link="hotel_pan_sixth_6in_223"/>
  </joint>
  <link name="hotel_pan_full_6in_202">
    <!-- simpler, box collision geo when we don't care about serving from this pan -->
    <!-- TODO: bounding box for racked utensil -->
    <collision>
      <origin rpy="0 0 -1.5707963267948966" xyz="0 0 0.0834"/>
      <geometry>
        <box size="0.53 0.34 0.17"/>
      </geometry>
    </collision>
    <visual>
      <origin rpy="0 0 -1.5707963267948966" xyz="0 0 0.0834"/>
      <geometry>
        <box size="0.53 0.34 0.17"/>
      </geometry>
    </visual>
    <!-- accurate collision geo for pan -->
    <!-- TODO: fix collision geo, this is just copied over from hotel_pan_sixth_6in -->
    <!-- Should be accuate now, measured manually and cross referenced to online vendors -->
  </link>
  <joint name="back_pans_center_to_hotel_pan_full_6in_202" type="fixed">
    <origin rpy="0 0 -1.5707963267948966" xyz="0 -0.325 -0.175"/>
    <parent link="back_pans_center"/>
    <child link="hotel_pan_full_6in_202"/>
  </joint>
  <drake:collision_filter_group name="hotel_pans">
    <drake:member link="low_boy_3pan_east"/>
    <drake:member link="low_boy_3pan_west"/>
    <drake:member link="hotel_pan_third_6in_000"/>
    <drake:member link="hotel_pan_third_6in_010"/>
    <drake:member link="hotel_pan_third_6in_020"/>
    <drake:member link="hotel_pan_full_6in_001"/>
    <drake:member link="hotel_pan_sixth_6in_004"/>
    <drake:member link="hotel_pan_sixth_6in_014"/>
    <drake:member link="hotel_pan_sixth_6in_024"/>
    <drake:member link="hotel_pan_sixth_6in_005"/>
    <drake:member link="hotel_pan_sixth_6in_015"/>
    <drake:member link="hotel_pan_sixth_6in_025"/>
    <drake:member link="hotel_pan_full_6in_200"/>
    <drake:member link="hotel_pan_sixth_6in_202"/>
    <drake:member link="hotel_pan_sixth_6in_212"/>
    <drake:member link="hotel_pan_sixth_6in_222"/>
    <drake:member link="hotel_pan_sixth_6in_203"/>
    <drake:member link="hotel_pan_sixth_6in_213"/>
    <drake:member link="hotel_pan_sixth_6in_223"/>
    <drake:member link="hotel_pan_full_6in_202"/>
    <drake:ignored_collision_filter_group name="base"/>
    <drake:ignored_collision_filter_group name="hotel_pans"/>
  </drake:collision_filter_group>
  <link name="nema_corner"/>
  <joint name="base_link_to_nema_corner" type="fixed">
    <origin rpy="0 0 0" xyz="0.173 -0.246 -0.0862"/>
    <parent link="base_link"/>
    <child link="nema_corner"/>
  </joint>
  <!-- Franka Robotic Arms  (will later be Helping Hand/FRANKA combo)-->
  <link name="js_franka_base_assem"/>
  <joint name="base_link_to_js_franka_base_assem_joint" type="fixed">
    <parent link="base_link"/>
    <child link="js_franka_base_assem"/>
    <origin rpy="0 0 0" xyz="0 0 0"/>
  </joint>
  <!-- robot base - collision only -->
  <link name="franka_robot_base">
    <collision>
      <origin rpy="0 0 0" xyz="0 0 0.0147"/>
      <geometry>
        <sphere radius="0.190"/>
      </geometry>
    </collision>
    <visual>
      <origin rpy="0 0 0" xyz="0 0 0.0147"/>
      <geometry>
        <sphere radius="0.190"/>
      </geometry>
    </visual>
  </link>
  <joint name="js_franka_base_assem_to_robot_base" type="fixed">
    <parent link="js_franka_base_assem"/>
    <child link="franka_robot_base"/>
  </joint>
  <joint name="franka_joint_js_franka_base_assem" type="fixed">
    <parent link="js_franka_base_assem"/>
    <child link="franka_link0"/>
    <origin rpy="0 0 1.5708" xyz="0 0 0"/>
  </joint>
  <link name="franka_link0">
    <inertial>
      <mass value="2.92"/>
      <origin rpy="0 0 0" xyz="-0.025566 -2.88e-05 0.057332"/>
      <inertia ixx="0.00782229414331" ixy="-1.56191622996e-05" ixz="-0.00126005738123" iyy="0.0109027971813" iyz="1.08233858202e-05" izz="0.0102355503949"/>
    </inertial>
    <collision>
      <origin rpy="0 1.5707963267948966 0" xyz="-0.075 0 0.06"/>
      <geometry>
        <cylinder length="0.03" radius="0.075"/>
      </geometry>
    </collision>
    <visual>
      <origin rpy="0 1.5707963267948966 0" xyz="-0.075 0 0.06"/>
      <geometry>
        <cylinder length="0.03" radius="0.075"/>
      </geometry>
    </visual>
    <collision>
      <origin rpy="0 0 0" xyz="-0.06 0 0.06"/>
      <geometry>
        <sphere radius="0.075"/>
      </geometry>
    </collision>
    <visual>
      <origin rpy="0 0 0" xyz="-0.06 0 0.06"/>
      <geometry>
        <sphere radius="0.075"/>
      </geometry>
    </visual>
    <collision>
      <origin rpy="0 0 0" xyz="-0.09 0 0.06"/>
      <geometry>
        <sphere radius="0.075"/>
      </geometry>
    </collision>
    <visual>
      <origin rpy="0 0 0" xyz="-0.09 0 0.06"/>
      <geometry>
        <sphere radius="0.075"/>
      </geometry>
    </visual>
  </link>
  <link name="franka_link1">
    <inertial>
      <mass value="2.74"/>
      <origin rpy="0 0 0" xyz="0 -0.0324958 -0.0675818"/>
      <inertia ixx="0.0180416958283" ixy="0.0" ixz="0.0" iyy="0.0159136071891" iyz="0.0046758424612" izz="0.00620690827127"/>
    </inertial>
    <collision>
      <origin rpy="0 0 0" xyz="0 0 -0.1915"/>
      <geometry>
        <cylinder length="0.2830" radius="0.075"/>
      </geometry>
    </collision>
    <visual>
      <origin rpy="0 0 0" xyz="0 0 -0.1915"/>
      <geometry>
        <cylinder length="0.2830" radius="0.075"/>
      </geometry>
    </visual>
    <collision>
      <origin rpy="0 0 0" xyz="0 0 -0.333"/>
      <geometry>
        <sphere radius="0.075"/>
      </geometry>
    </collision>
    <visual>
      <origin rpy="0 0 0" xyz="0 0 -0.333"/>
      <geometry>
        <sphere radius="0.075"/>
      </geometry>
    </visual>
    <collision>
      <origin rpy="0 0 0" xyz="0 0 -0.05"/>
      <geometry>
        <sphere radius="0.075"/>
      </geometry>
    </collision>
    <visual>
      <origin rpy="0 0 0" xyz="0 0 -0.05"/>
      <geometry>
        <sphere radius="0.075"/>
      </geometry>
    </visual>
  </link>
  <joint name="franka_joint1" type="revolute">
    <!-- Safety controller is not supported by drake URDF parsing. -->
    <!-- <safety_controller k_position="100.0" k_velocity="40.0" soft_lower_limit="-2.8973" soft_upper_limit="2.8973"/> -->
    <origin rpy="0 0 0" xyz="0 0 0.333"/>
    <parent link="franka_link0"/>
    <child link="franka_link1"/>
    <axis xyz="0 0 1"/>
    <limit effort="87" lower="-2.8773" upper="2.8773" velocity="2.1750"/>
  </joint>
  <link name="franka_link2">
    <inertial>
      <mass value="2.74"/>
      <origin rpy="0 0 0" xyz="0 -0.06861 0.0322285"/>
      <inertia ixx="0.0182856182281" ixy="0.0" ixz="0.0" iyy="0.00621358421175" iyz="-0.00472844221905" izz="0.0161514346309"/>
    </inertial>
    <collision>
      <origin rpy="0 0 0" xyz="0 0 0"/>
      <geometry>
        <cylinder length="0.12" radius="0.075"/>
      </geometry>
    </collision>
    <visual>
      <origin rpy="0 0 0" xyz="0 0 0"/>
      <geometry>
        <cylinder length="0.12" radius="0.075"/>
      </geometry>
    </visual>
    <collision>
      <origin rpy="0 0 0" xyz="0 0 -0.06"/>
      <geometry>
        <sphere radius="0.075"/>
      </geometry>
    </collision>
    <visual>
      <origin rpy="0 0 0" xyz="0 0 -0.06"/>
      <geometry>
        <sphere radius="0.075"/>
      </geometry>
    </visual>
    <collision>
      <origin rpy="0 0 0" xyz="0 0 0.06"/>
      <geometry>
        <sphere radius="0.075"/>
      </geometry>
    </collision>
    <visual>
      <origin rpy="0 0 0" xyz="0 0 0.06"/>
      <geometry>
        <sphere radius="0.075"/>
      </geometry>
    </visual>
  </link>
  <joint name="franka_joint2" type="revolute">
    <!-- <safety_controller k_position="100.0" k_velocity="40.0" soft_lower_limit="-1.7628" soft_upper_limit="1.7628"/> -->
    <origin rpy="-1.5707963267948966 0 0" xyz="0 0 0"/>
    <parent link="franka_link1"/>
    <child link="franka_link2"/>
    <axis xyz="0 0 1"/>
    <limit effort="87" lower="-1.7428" upper="1.7428" velocity="2.1750"/>
  </joint>
  <link name="franka_link3">
    <inertial>
      <mass value="2.38"/>
      <origin rpy="0 0 0" xyz="0.0469893 0.0316374 -0.031704"/>
      <inertia ixx="0.00771376630908" ixy="-0.00248490625138" ixz="-0.00332147581033" iyy="0.00989108008727" iyz="-0.00217796151484" izz="0.00811723558464"/>
    </inertial>
    <collision>
      <origin rpy="0 0 0" xyz="0 0 -0.145"/>
      <geometry>
        <cylinder length="0.15" radius="0.075"/>
      </geometry>
    </collision>
    <visual>
      <origin rpy="0 0 0" xyz="0 0 -0.145"/>
      <geometry>
        <cylinder length="0.15" radius="0.075"/>
      </geometry>
    </visual>
    <collision>
      <origin rpy="0 0 0" xyz="0 0 -0.22"/>
      <geometry>
        <sphere radius="0.075"/>
      </geometry>
    </collision>
    <visual>
      <origin rpy="0 0 0" xyz="0 0 -0.22"/>
      <geometry>
        <sphere radius="0.075"/>
      </geometry>
    </visual>
    <collision>
      <origin rpy="0 0 0" xyz="0 0 -0.07"/>
      <geometry>
        <sphere radius="0.075"/>
      </geometry>
    </collision>
    <visual>
      <origin rpy="0 0 0" xyz="0 0 -0.07"/>
      <geometry>
        <sphere radius="0.075"/>
      </geometry>
    </visual>
  </link>
  <joint name="franka_joint3" type="revolute">
    <!-- <safety_controller k_position="100.0" k_velocity="40.0" soft_lower_limit="-2.8973" soft_upper_limit="2.8973"/> -->
    <origin rpy="1.5707963267948966 0 0" xyz="0 -0.316 0"/>
    <parent link="franka_link2"/>
    <child link="franka_link3"/>
    <axis xyz="0 0 1"/>
    <limit effort="87" lower="-2.8773" upper="2.8773" velocity="2.1750"/>
  </joint>
  <link name="franka_link4">
    <inertial>
      <mass value="2.38"/>
      <origin rpy="0 0 0" xyz="-0.0360446 0.0336853 0.031882"/>
      <inertia ixx="0.00799663881132" ixy="0.00347095570217" ixz="-0.00241222942995" iyy="0.00825390705278" iyz="0.00235774044121" izz="0.0102515004345"/>
    </inertial>
    <collision>
      <origin rpy="0 0 0" xyz="0 0 0"/>
      <geometry>
        <cylinder length="0.12" radius="0.075"/>
      </geometry>
    </collision>
    <visual>
      <origin rpy="0 0 0" xyz="0 0 0"/>
      <geometry>
        <cylinder length="0.12" radius="0.075"/>
      </geometry>
    </visual>
    <collision>
      <origin rpy="0 0 0" xyz="0 0 0.06"/>
      <geometry>
        <sphere radius="0.075"/>
      </geometry>
    </collision>
    <visual>
      <origin rpy="0 0 0" xyz="0 0 0.06"/>
      <geometry>
        <sphere radius="0.075"/>
      </geometry>
    </visual>
    <collision>
      <origin rpy="0 0 0" xyz="0 0 -0.06"/>
      <geometry>
        <sphere radius="0.075"/>
      </geometry>
    </collision>
    <visual>
      <origin rpy="0 0 0" xyz="0 0 -0.06"/>
      <geometry>
        <sphere radius="0.075"/>
      </geometry>
    </visual>
  </link>
  <joint name="franka_joint4" type="revolute">
    <!-- <safety_controller k_position="100.0" k_velocity="40.0" soft_lower_limit="-3.0718" soft_upper_limit="-0.0698"/> -->
    <origin rpy="1.5707963267948966 0 0" xyz="0.0825 0 0"/>
    <parent link="franka_link3"/>
    <child link="franka_link4"/>
    <axis xyz="0 0 1"/>
    <limit effort="87" lower="-3.0518" upper="-0.0898" velocity="2.1750"/>
  </joint>
  <link name="franka_link5">
    <inertial>
      <mass value="2.74"/>
      <origin rpy="0 0 0" xyz="0 0.0610427 -0.104176"/>
      <inertia ixx="0.030371374513" ixy="6.50283587108e-07" ixz="-1.05129179916e-05" iyy="0.0288752887402" iyz="-0.00775653445787" izz="0.00444134056164"/>
    </inertial>
    <collision>
      <origin rpy="0 0 0" xyz="0 0 -0.26"/>
      <geometry>
        <cylinder length="0.1" radius="0.075"/>
      </geometry>
    </collision>
    <visual>
      <origin rpy="0 0 0" xyz="0 0 -0.26"/>
      <geometry>
        <cylinder length="0.1" radius="0.075"/>
      </geometry>
    </visual>
    <collision>
      <origin rpy="0 0 0" xyz="0 0 -0.31"/>
      <geometry>
        <sphere radius="0.075"/>
      </geometry>
    </collision>
    <visual>
      <origin rpy="0 0 0" xyz="0 0 -0.31"/>
      <geometry>
        <sphere radius="0.075"/>
      </geometry>
    </visual>
    <collision>
      <origin rpy="0 0 0" xyz="0 0 -0.21"/>
      <geometry>
        <sphere radius="0.075"/>
      </geometry>
    </collision>
    <visual>
      <origin rpy="0 0 0" xyz="0 0 -0.21"/>
      <geometry>
        <sphere radius="0.075"/>
      </geometry>
    </visual>
    <collision>
      <origin rpy="0 0 0" xyz="0 0.08 -0.13"/>
      <geometry>
        <cylinder length="0.14" radius="0.04"/>
      </geometry>
    </collision>
    <visual>
      <origin rpy="0 0 0" xyz="0 0.08 -0.13"/>
      <geometry>
        <cylinder length="0.14" radius="0.04"/>
      </geometry>
    </visual>
    <collision>
      <origin rpy="0 0 0" xyz="0 0.08 -0.06"/>
      <geometry>
        <sphere radius="0.04"/>
      </geometry>
    </collision>
    <visual>
      <origin rpy="0 0 0" xyz="0 0.08 -0.06"/>
      <geometry>
        <sphere radius="0.04"/>
      </geometry>
    </visual>
    <collision>
      <origin rpy="0 0 0" xyz="0 0.08 -0.20"/>
      <geometry>
        <sphere radius="0.04"/>
      </geometry>
    </collision>
    <visual>
      <origin rpy="0 0 0" xyz="0 0.08 -0.20"/>
      <geometry>
        <sphere radius="0.04"/>
      </geometry>
    </visual>
  </link>
  <joint name="franka_joint5" type="revolute">
    <!-- <safety_controller k_position="100.0" k_velocity="40.0" soft_lower_limit="-2.8973" soft_upper_limit="2.8973"/> -->
    <origin rpy="-1.5707963267948966 0 0" xyz="-0.0825 0.384 0"/>
    <parent link="franka_link4"/>
    <child link="franka_link5"/>
    <axis xyz="0 0 1"/>
    <limit effort="12" lower="-2.8773" upper="2.8773" velocity="2.6100"/>
  </joint>
  <link name="franka_link6">
    <inertial>
      <mass value="1.55"/>
      <origin rpy="0 0 0" xyz="0.0510509 0.009108 0.0106343"/>
      <inertia ixx="0.00303336450376" ixy="-0.000437276865508" ixz="0.000629257294877" iyy="0.00404479911567" iyz="0.000130472021025" izz="0.00558234286039"/>
    </inertial>
    <collision>
      <origin rpy="0 0 0" xyz="0 0 -0.03"/>
      <geometry>
        <cylinder length="0.08" radius="0.065"/>
      </geometry>
    </collision>
    <visual>
      <origin rpy="0 0 0" xyz="0 0 -0.03"/>
      <geometry>
        <cylinder length="0.08" radius="0.065"/>
      </geometry>
    </visual>
    <collision>
      <origin rpy="0 0 0" xyz="0 0 0.01"/>
      <geometry>
        <sphere radius="0.065"/>
      </geometry>
    </collision>
    <visual>
      <origin rpy="0 0 0" xyz="0 0 0.01"/>
      <geometry>
        <sphere radius="0.065"/>
      </geometry>
    </visual>
    <collision>
      <origin rpy="0 0 0" xyz="0 0 -0.07"/>
      <geometry>
        <sphere radius="0.065"/>
      </geometry>
    </collision>
    <visual>
      <origin rpy="0 0 0" xyz="0 0 -0.07"/>
      <geometry>
        <sphere radius="0.065"/>
      </geometry>
    </visual>
  </link>
  <joint name="franka_joint6" type="revolute">
    <!-- <safety_controller k_position="100.0" k_velocity="40.0" soft_lower_limit="-0.0175" soft_upper_limit="3.7525"/> -->
    <origin rpy="1.5707963267948966 0 0" xyz="0 0 0"/>
    <parent link="franka_link5"/>
    <child link="franka_link6"/>
    <axis xyz="0 0 1"/>
    <limit effort="12" lower="0.0075" upper="3.6825" velocity="2.6100"/>
  </joint>
  <link name="franka_link7">
    <inertial>
      <mass value="0.54"/>
      <origin rpy="0 0 0" xyz="0.0109695 0.0107965 0.0650411"/>
      <inertia ixx="0.000888868887021" ixy="-0.00012239074652" ixz="3.98699829666e-05" iyy="0.000888001373233" iyz="-9.33825115206e-05" izz="0.0007176834609"/>
    </inertial>
    <collision>
      <origin rpy="0 0 0" xyz="0 0 0.01"/>
      <geometry>
        <cylinder length="0.14" radius="0.055"/>
      </geometry>
    </collision>
    <visual>
      <origin rpy="0 0 0" xyz="0 0 0.01"/>
      <geometry>
        <cylinder length="0.14" radius="0.055"/>
      </geometry>
    </visual>
    <collision>
      <origin rpy="0 0 0" xyz="0 0 0.08"/>
      <geometry>
        <sphere radius="0.055"/>
      </geometry>
    </collision>
    <visual>
      <origin rpy="0 0 0" xyz="0 0 0.08"/>
      <geometry>
        <sphere radius="0.055"/>
      </geometry>
    </visual>
    <collision>
      <origin rpy="0 0 0" xyz="0 0 -0.06"/>
      <geometry>
        <sphere radius="0.055"/>
      </geometry>
    </collision>
    <visual>
      <origin rpy="0 0 0" xyz="0 0 -0.06"/>
      <geometry>
        <sphere radius="0.055"/>
      </geometry>
    </visual>
  </link>
  <joint name="franka_joint7" type="revolute">
    <!-- <safety_controller k_position="100.0" k_velocity="40.0" soft_lower_limit="-2.8973" soft_upper_limit="2.8973"/> -->
    <origin rpy="1.5707963267948966 0 0" xyz="0.088 0 0"/>
    <parent link="franka_link6"/>
    <child link="franka_link7"/>
    <axis xyz="0 0 1"/>
    <limit effort="12" lower="-2.8773" upper="2.8773" velocity="2.6100"/>
  </joint>
  <link name="franka_link8">
    <collision>
      <origin rpy="3.141592653589793 1.5707963267948966 1.5707963267948966" xyz="0.0424 0.0424 -0.0250"/>
      <geometry>
        <cylinder length="0.01" radius="0.045"/>
      </geometry>
    </collision>
    <visual>
      <origin rpy="3.141592653589793 1.5707963267948966 1.5707963267948966" xyz="0.0424 0.0424 -0.0250"/>
      <geometry>
        <cylinder length="0.01" radius="0.045"/>
      </geometry>
    </visual>
    <collision>
      <origin rpy="0 0 0" xyz="0.0424 0.0424 -0.02"/>
      <geometry>
        <sphere radius="0.045"/>
      </geometry>
    </collision>
    <visual>
      <origin rpy="0 0 0" xyz="0.0424 0.0424 -0.02"/>
      <geometry>
        <sphere radius="0.045"/>
      </geometry>
    </visual>
    <collision>
      <origin rpy="0 0 0" xyz="0.0424 0.0424 -0.03"/>
      <geometry>
        <sphere radius="0.045"/>
      </geometry>
    </collision>
    <visual>
      <origin rpy="0 0 0" xyz="0.0424 0.0424 -0.03"/>
      <geometry>
        <sphere radius="0.045"/>
      </geometry>
    </visual>
  </link>
  <joint name="franka_joint8" type="fixed">
    <origin rpy="0 0 0" xyz="0 0 0.107"/>
    <parent link="franka_link7"/>
    <child link="franka_link8"/>
  </joint>
  <!-- j1="-1.1154978953077082" j2="-0.2693635778607361" j3="0.4818306812721388" j4="-1.8567957659645953" j5="0.07724899751232778" j6="1.6229217918713887" j7="-2.8619398868510375" /> -->
  <link name="franka_tool_location"/>
  <joint name="franka_head_to_tool_location" type="fixed">
    <origin rpy="0 0 0" xyz="-0.00312 0 0.08567"/>
    <parent link="franka_head"/>
    <child link="franka_tool_location"/>
  </joint>
  <!-- Hacky fix to keep tool tip and other tool frames in the same location relative to franka head -->
  <link name="franka_temp_tool_location"/>
  <joint name="franka_tool_location_to_temp_tool_location" type="fixed">
    <origin rpy="0 0 0" xyz="0 0 -0.014"/>
    <parent link="franka_tool_location"/>
    <child link="franka_temp_tool_location"/>
  </joint>
  <link name="lidar_color_optical_frame"/>
  <joint name="franka_tool_location_to_lidar_color_optical_frame" type="fixed">
    <origin rpy="0 0 1.5707963267948966" xyz="0.014 0 0.03293"/>
    <parent link="franka_tool_location"/>
    <child link="lidar_color_optical_frame"/>
  </joint>
  <link name="franka_head">
    <inertial>
      <mass value="1.112"/>
      <origin rpy="0 0 0" xyz="0.017 0.003 0.038"/>
      <inertia ixx="0.002" ixy="0.000" ixz="-0.001" iyy="0.003" iyz="0.000" izz="0.002"/>
    </inertial>
    <!-- concentric cyl -->
    <collision>
      <origin rpy="0 0 0" xyz="0 0 0.0308"/>
      <geometry>
        <cylinder length="0.124" radius="0.05"/>
      </geometry>
    </collision>
    <visual>
      <origin rpy="0 0 0" xyz="0 0 0.0308"/>
      <geometry>
        <cylinder length="0.124" radius="0.05"/>
      </geometry>
    </visual>
  </link>
  <joint name="franka_link8_to_franka_head" type="fixed">
    <parent link="franka_link8"/>
    <child link="franka_head"/>
    <origin rpy="0 0 0.785398" xyz="0.0 0.000 0.0075"/>
  </joint>
  <joint name="franka_link8_to_franka_head_box" type="fixed">
    <parent link="franka_link8"/>
    <child link="franka_head_box"/>
    <origin rpy="0 0 0" xyz="0 0 0"/>
  </joint>
  <link name="franka_head_box">
    <collision>
      <origin rpy="0 0 0.785398" xyz="0.0424 0.0424 0.02"/>
      <geometry>
        <box size="0.06 0.085 0.05"/>
      </geometry>
    </collision>
    <visual>
      <origin rpy="0 0 0.785398" xyz="0.0424 0.0424 0.02"/>
      <geometry>
        <box size="0.06 0.085 0.05"/>
      </geometry>
    </visual>
    <collision>
      <origin rpy="0 0 0.785398" xyz="0.034 0.034 0.04"/>
      <geometry>
        <box size="0.04 0.115 0.05"/>
      </geometry>
    </collision>
    <visual>
      <origin rpy="0 0 0.785398" xyz="0.034 0.034 0.04"/>
      <geometry>
        <box size="0.04 0.115 0.05"/>
      </geometry>
    </visual>
  </link>
  <link name="franka_head_fangs">
    <collision>
      <origin rpy="0 0 0" xyz="0.02 0.015 0"/>
      <geometry>
        <sphere radius="0.015"/>
      </geometry>
    </collision>
    <visual>
      <origin rpy="0 0 0" xyz="0.02 0.015 0"/>
      <geometry>
        <sphere radius="0.015"/>
      </geometry>
    </visual>
    <collision>
      <origin rpy="0 0 0" xyz="-0.028 0.01 0"/>
      <geometry>
        <sphere radius="0.015"/>
      </geometry>
    </collision>
    <visual>
      <origin rpy="0 0 0" xyz="-0.028 0.01 0"/>
      <geometry>
        <sphere radius="0.015"/>
      </geometry>
    </visual>
    <collision>
      <origin rpy="0 0 0" xyz="0.02 -0.015 0"/>
      <geometry>
        <sphere radius="0.015"/>
      </geometry>
    </collision>
    <visual>
      <origin rpy="0 0 0" xyz="0.02 -0.015 0"/>
      <geometry>
        <sphere radius="0.015"/>
      </geometry>
    </visual>
    <collision>
      <origin rpy="0 0 0" xyz="-0.028 -0.01 0"/>
      <geometry>
        <sphere radius="0.015"/>
      </geometry>
    </collision>
    <visual>
      <origin rpy="0 0 0" xyz="-0.028 -0.01 0"/>
      <geometry>
        <sphere radius="0.015"/>
      </geometry>
    </visual>
  </link>
  <joint name="franka_head_to_franka_fangs" type="fixed">
    <parent link="franka_head"/>
    <child link="franka_head_fangs"/>
    <origin rpy="0 0 0" xyz="-0.003 0.000 0.1"/>
  </joint>
  <link name="cg_base">
    <!-- base cyl -->
    <collision>
      <origin rpy="0 0 0" xyz="0 -.04 -0.0625"/>
      <geometry>
        <cylinder length="0.125" radius="0.17526"/>
      </geometry>
    </collision>
    <visual>
      <origin rpy="0 0 0" xyz="0 -.04 -0.0625"/>
      <geometry>
        <cylinder length="0.125" radius="0.17526"/>
      </geometry>
    </visual>
    <!-- electrical box underneath -->
    <collision>
      <origin rpy="0 0 0" xyz="-0.0094 0 -0.4028"/>
      <geometry>
        <box size="0.2773 0.508 0.6096"/>
      </geometry>
    </collision>
    <visual>
      <origin rpy="0 0 0" xyz="-0.0094 0 -0.4028"/>
      <geometry>
        <box size="0.2773 0.508 0.6096"/>
      </geometry>
    </visual>
    <!-- plate -->
    <collision>
      <origin rpy="0 0 0" xyz="0 0 -0.14250000000000002"/>
      <geometry>
        <box size="0.48 0.6 0.125"/>
      </geometry>
    </collision>
    <visual>
      <origin rpy="0 0 0" xyz="0 0 -0.14250000000000002"/>
      <geometry>
        <box size="0.48 0.6 0.125"/>
      </geometry>
    </visual>
    <!-- Connects Assembly to parent -->
  </link>
  <joint name="js_franka_base_assem_to_cg_base" type="fixed">
    <parent link="js_franka_base_assem"/>
    <child link="cg_base"/>
    <origin rpy="0 0 0" xyz="0 0 0"/>
  </joint>
  <link name="realsense_base_link"/>
  <joint name="franka_link8_to_realsense_base_link" type="fixed">
    <origin rpy="0 -1.5707963267948966 0" xyz="0.0625 0.007 0.041"/>
    <parent link="franka_head"/>
    <child link="realsense_base_link"/>
  </joint>
  <!-- Include gazebo plugins -->
  <gazebo>
    <plugin filename="libforce_joint.so" name="force_joint"/>
    <plugin filename="librealsense_gazebo_plugin.so" name="realsense_plugin"/>
  </gazebo>
  <!-- Set Camera settings -->
  <gazebo reference="realsense_color_frame">
    <sensor name="color" type="camera">
      <pose frame="">0 0 0 0 0 0</pose>
      <camera name="__default__">
        <horizontal_fov>1.211</horizontal_fov>
        <image>
          <width>640</width>
          <height>480</height>
          <format>RGB_INT8</format>
        </image>
        <clip>
          <near>0.105</near>
          <far>10</far>
        </clip>
        <noise>
          <type>gaussian</type>
          <mean>0.0</mean>
          <stddev>0.007</stddev>
        </noise>
      </camera>
      <always_on>1</always_on>
      <update_rate>30</update_rate>
      <visualize>1</visualize>
    </sensor>
    <sensor name="ired1" type="camera">
      <pose frame="">0 0 0 0 0 0</pose>
      <camera name="__default__">
        <horizontal_fov>1.211</horizontal_fov>
        <image>
          <width>640</width>
          <height>480</height>
          <format>RGB_INT8</format>
        </image>
        <clip>
          <near>0.105</near>
          <far>10</far>
        </clip>
        <noise>
          <type>gaussian</type>
          <mean>0.0</mean>
          <stddev>0.007</stddev>
        </noise>
      </camera>
      <always_on>1</always_on>
      <update_rate>30</update_rate>
      <visualize>0</visualize>
    </sensor>
    <sensor name="ired2" type="camera">
      <pose frame="">0 0 0 0 0 0</pose>
      <camera name="__default__">
        <horizontal_fov>1.211</horizontal_fov>
        <image>
          <width>640</width>
          <height>480</height>
          <format>RGB_INT8</format>
        </image>
        <clip>
          <near>0.105</near>
          <far>10</far>
        </clip>
        <noise>
          <type>gaussian</type>
          <mean>0.0</mean>
          <stddev>0.007</stddev>
        </noise>
      </camera>
      <always_on>1</always_on>
      <update_rate>30</update_rate>
      <visualize>0</visualize>
    </sensor>
    <sensor name="depth" type="depth">
      <pose frame="">0 0 0 0 0 0</pose>
      <camera name="__default__">
        <horizontal_fov>1.518</horizontal_fov>
        <image>
          <width>640</width>
          <height>480</height>
          <format>RGB_INT8</format>
        </image>
        <clip>
          <near>0.105</near>
          <far>10</far>
        </clip>
        <noise>
          <type>gaussian</type>
          <mean>0.0</mean>
          <stddev>0.007</stddev>
        </noise>
      </camera>
      <always_on>1</always_on>
      <update_rate>30</update_rate>
      <visualize>0</visualize>
    </sensor>
  </gazebo>
  <!-- camera body, with origin at bottom screw mount -->
  <joint name="realsense_joint" type="fixed">
    <origin rpy="0 0 0" xyz="0 0 0"/>
    <parent link="realsense_base_link"/>
    <child link="realsense_bottom_screw_frame"/>
  </joint>
  <link name="realsense_bottom_screw_frame"/>
  <joint name="realsense_link_joint" type="fixed">
    <origin rpy="0 0 0" xyz="0 0.0175 0.0125"/>
    <parent link="realsense_bottom_screw_frame"/>
    <child link="realsense_link"/>
  </joint>
  <link name="realsense_link">
    <collision>
      <origin rpy="0 0 0" xyz="0 -0.0175 0"/>
      <geometry>
        <box size="0.02505 0.09 0.025"/>
      </geometry>
    </collision>
    <visual>
      <origin rpy="0 0 0" xyz="0 -0.0175 0"/>
      <geometry>
        <box size="0.02505 0.09 0.025"/>
      </geometry>
    </visual>
    <inertial>
      <!-- The following are not reliable values, and should not be used for modeling -->
      <mass value="0.564"/>
      <origin xyz="0 0 0"/>
      <inertia ixx="0.003881243" ixy="0.0" ixz="0.0" iyy="0.000498940" iyz="0.0" izz="0.003879257"/>
    </inertial>
  </link>
  <!-- camera depth joints and links -->
  <joint name="realsense_depth_joint" type="fixed">
    <origin rpy="0 0 0" xyz="0 0 0"/>
    <parent link="realsense_link"/>
    <child link="realsense_depth_frame"/>
  </joint>
  <link name="realsense_depth_frame"/>
  <joint name="realsense_depth_optical_joint" type="fixed">
    <origin rpy="-1.5707963267948966 0 -1.5707963267948966" xyz="0 0 0"/>
    <parent link="realsense_depth_frame"/>
    <child link="realsense_depth_optical_frame"/>
  </joint>
  <link name="realsense_depth_optical_frame"/>
  <!-- camera left IR joints and links -->
  <joint name="realsense_left_ir_joint" type="fixed">
    <origin rpy="0 0 0" xyz="0 0.0 0"/>
    <parent link="realsense_depth_frame"/>
    <child link="realsense_left_ir_frame"/>
  </joint>
  <link name="realsense_left_ir_frame"/>
  <joint name="realsense_left_ir_optical_joint" type="fixed">
    <origin rpy="-1.5707963267948966 0 -1.5707963267948966" xyz="0 0 0"/>
    <parent link="realsense_left_ir_frame"/>
    <child link="realsense_left_ir_optical_frame"/>
  </joint>
  <link name="realsense_left_ir_optical_frame"/>
  <!-- camera right IR joints and links -->
  <joint name="realsense_right_ir_joint" type="fixed">
    <origin rpy="0 0 0" xyz="0 -0.05 0"/>
    <parent link="realsense_depth_frame"/>
    <child link="realsense_right_ir_frame"/>
  </joint>
  <link name="realsense_right_ir_frame"/>
  <joint name="realsense_right_ir_optical_joint" type="fixed">
    <origin rpy="-1.5707963267948966 0 -1.5707963267948966" xyz="0 0 0"/>
    <parent link="realsense_right_ir_frame"/>
    <child link="realsense_right_ir_optical_frame"/>
  </joint>
  <link name="realsense_right_ir_optical_frame"/>
  <!-- camera color joints and links -->
  <joint name="realsense_color_joint" type="fixed">
    <origin rpy="0 0 0" xyz="0 0.015 0"/>
    <parent link="realsense_depth_frame"/>
    <child link="realsense_color_frame"/>
  </joint>
  <link name="realsense_color_frame"/>
  <joint name="realsense_color_uncorrected_optical_joint" type="fixed">
    <origin rpy="-1.5707963267948966 0 -1.5707963267948966" xyz="0 0 0"/>
    <parent link="realsense_color_frame"/>
    <child link="realsense_uncorrected_color_optical_frame"/>
  </joint>
  <link name="realsense_uncorrected_color_optical_frame"/>
  <joint name="realsense_color_optical_joint" type="fixed">
    <origin rpy="0.0 0.0 0.0" xyz="0.0 0.0 0.0"/>
    <parent link="realsense_uncorrected_color_optical_frame"/>
    <child link="realsense_color_optical_frame"/>
  </joint>
  <link name="realsense_color_optical_frame"/>
  <link name="realsense_tag_alignment_frame"/>
  <joint name="realsense_color_tag_joint" type="fixed">
    <origin rpy="0 3.141592653589793 0" xyz="0 0 0"/>
    <parent link="realsense_color_optical_frame"/>
    <child link="realsense_tag_alignment_frame"/>
  </joint>
  <drake:collision_filter_group name="base">
    <drake:member link="base_link"/>
    <drake:member link="js_franka_base_assem"/>
    <drake:member link="cg_base"/>
    <drake:member link="franka_robot_base"/>
    <drake:member link="franka_link0"/>
    <drake:member link="franka_link1"/>
    <drake:member link="franka_link2"/>
    <drake:member link="franka_link3"/>
    <drake:member link="franka_link4"/>
    <drake:ignored_collision_filter_group name="base"/>
    <drake:ignored_collision_filter_group name="hotel_pans"/>
  </drake:collision_filter_group>
  <drake:collision_filter_group name="end_effector">
    <drake:member link="franka_link5"/>
    <drake:member link="franka_link6"/>
    <drake:member link="franka_link7"/>
    <drake:member link="franka_link8"/>
    <drake:member link="franka_head"/>
    <drake:member link="franka_head_fangs"/>
    <drake:member link="franka_head_box"/>
    <drake:member link="realsense_base_link"/>
    <drake:member link="realsense_link"/>
    <drake:ignored_collision_filter_group name="end_effector"/>
  </drake:collision_filter_group>
</robot>

